<?xml version="1.0" ?>
<robot name="orthopillar">

<link name="chassis">
    
    
    
    <collision name="collision">
    <origin xyz="0 0 0.2 "/>
      <geometry>
        <box size="0.6 0.3 0.3"/>
      </geometry>
    </collision>
    
    <visual name="visual">
      <geometry>
         <!-- <mesh filename="package://orthopillar_robot_spawner_pkg/models/ortho_meshes/meshes/orthopillar.stl" scale="0.25 0.25 0.25 " /> -->
      <box size="0.6 0.3 0.3"/>
      </geometry>
    </visual>
    
    <collision name="caster_collision">
     <origin xyz="0 0.15 -0.15"/>
      <geometry>
        <sphere radius=".05"/>
      </geometry>
 </collision>
    
    <visual name="caster_visual">
     <origin xyz="0 0.15 -0.15"/>
      <geometry>
        <sphere radius=".05"/>
      </geometry>
    </visual>
  </link>
  


  <link name="right_wheel">
    <inertial>
      <mass value="1"/>
      <origin rpy="0  0  0" xyz="0  0  0"/>
      <inertia ixx="100" ixy="0" ixz="0" iyy="100" iyz="0" izz="100"/>
    </inertial>
    <!-- <pose>0.15 -0.13 0.1 0 1.5707 0</pose> -->
    <collision name="collision">
      <origin xyz="0.15 -0.13 0.1 " rpy=" 0 1.5707 0" />
      <geometry>
        <cylinder length=".05" radius=".1"/>
      </geometry>
    </collision>
    
    <visual name="visual">
    <origin xyz="0.15 -0.13 0.1 " rpy=" 0 1.5707 0" />
      <geometry>
        <cylinder length=".05" radius=".1"/>
      </geometry>
    </visual>
  </link>

<link name="left_wheel">
    <inertial>
      <mass value="1"/>
      <origin rpy="0  0  0" xyz="0  0  0"/>
      <inertia ixx="100" ixy="0" ixz="0" iyy="100" iyz="0" izz="100"/>
    </inertial>
  <!-- <pose>-0.15 -0.13 0.1 0 1.5707 0</pose> -->
    <collision name="collision">
     <origin xyz="-0.15 -0.13 0.1 " rpy=" 0 1.5707 0" />
      <geometry>
        <cylinder length=".05" radius=".1"/>
      </geometry>
    </collision>
     
    <visual name="visual">
    <origin xyz="-0.15 -0.13 0.1 " rpy=" 0 1.5707 0" />
      <geometry>
        <cylinder length=".05" radius=".1"/>
      </geometry>
    </visual>
  </link>

  <joint name="left_wheel_hinge" type="continuous">
    <parent link="chassis"/>
    <child link="left_wheel"/>
    <origin rpy="0      0  0" xyz="0  0     0"/>
    <!-- <origin xyz="-0.15 -0.13 0.1 "/> -->
    <axis xyz="0   1   0"/>
    <limit effort="10000" velocity="1000"/>
    <joint_properties damping="1.0" friction="1.0"/>
   
  </joint>
  
  <joint name="right_wheel_hinge" type="continuous">
    <parent link="chassis"/>
    <child link="right_wheel"/>
    <origin rpy="0      0  0" xyz="0  0     0"/>
    <!-- <origin xyz="0.15 -0.13 0.1"/> -->
    <axis xyz="0  1   0"/>
    <limit effort="10000" velocity="1000"/>
    <joint_properties damping="1.0" friction="1.0"/>
  </joint>
  
  

  
    

 
  
    
  
  
  

  
  
  
  
  
  
</robot>
