<?xml version="1.0"?>
<robot name="orthopillar"
  xmlns:xacro="http://ros.org/wiki/xacro">
  <!-- _________________________________________________________Color_________________________________________________________-->

  <material name="Cyan">
    <color rgba="0 1.0 1.0 1.0"/>
  </material>

  <material name="Gray">
    <color rgba="0.5 0.5 0.5 1.0"/>
  </material>

  <!-- _________________________________________________________Robot Base_________________________________________________________ -->
  <link name="base_footprint"/>

  <joint name="base_joint" type="fixed">
    <parent link="base_footprint"/>
    <child link="base_link"/>
    <origin xyz="0.0 0.0 -0.15" rpy="0 0 0"/>
  </joint>

  <link name="base_link">
    <visual>
      <geometry>
        <box size="0.42 0.31 0.18"/>
      </geometry>
      <material name="Cyan"/>
    </visual>

    <collision>
      <geometry>
        <box size="0.42 0.31 0.18"/>
      </geometry>
    </collision>

    <inertial>
      <origin xyz="0.0 0.0 0.0" rpy="1.570796 0.0 1.570796"/>
      <mass value="15"/>
      <inertia ixx="0.261" ixy="0.0" ixz="0.0" iyy="0.340625" iyz="0.0" izz="0.160625"/>
    </inertial>
  </link>

  <!-- _________________________________________________________Wheel left_________________________________________________________ -->
  
  <joint name="drivewhl_l_joint" type="continuous">
    <parent link="base_link"/>
    <child link="drivewhl_l_link"/>
    <origin xyz="-0.12 0.18 -0.05" rpy="0 0 0"/>
    <axis xyz="0 1 0"/>
  </joint>

  <link name="drivewhl_l_link">
    <visual>
      <origin xyz="0 0 0" rpy="1.570796 0 0"/>
      <geometry>
        <cylinder radius="0.1" length="0.04"/>
      </geometry>
      <material name="Gray"/>
    </visual>

    <collision>
      <origin xyz="0 0 0" rpy="1.570796 0 0"/>
      <geometry>
        <cylinder radius="0.1" length="0.04"/>
      </geometry>
    </collision>

    <inertial>
      <origin xyz="0.0 0.0 0.0" rpy="1.570796 0.0 0.0"/>
      <mass value="0.5"/>
      <inertia ixx="0.001" ixy="0.0" ixz="0.0" iyy="0.001" iyz="0.0" izz="0.0025"/>
    </inertial>

  </link>

  <!-- _________________________________________________________Wheel right_________________________________________________________ -->
  
  <joint name="drivewhl_r_joint" type="continuous">
    <parent link="base_link"/>
    <child link="drivewhl_r_link"/>
    <origin xyz="-0.12 -0.18 -0.05" rpy="0 0 0"/>
    <axis xyz="0 1 0"/>
  </joint>

  <link name="drivewhl_r_link">
    <visual>
      <origin xyz="0 0 0" rpy="1.570796 0 0"/>
      <geometry>
        <cylinder radius="0.1" length="0.04"/>
      </geometry>
      <material name="Gray"/>
    </visual>

    <collision>
      <origin xyz="0 0 0" rpy="1.570796 0 0"/>
      <geometry>
        <cylinder radius="0.1" length="0.04"/>
      </geometry>
    </collision>

    <inertial>
      <origin xyz="0.0 0.0 0.0" rpy="1.570796 0.0 0.0"/>
      <mass value="0.5"/>
      <inertia ixx="0.001" ixy="0.0" ixz="0.0" iyy="0.001" iyz="0.0" izz="0.0025"/>
    </inertial>

  </link>

  <!-- _________________________________________________________Caster Wheel_________________________________________________________ -->

  <joint name="caster_joint" type="fixed">
    <parent link="base_link"/>
    <child link="front_caster"/>
    <origin xyz="0.2 0.0 -0.09" rpy="0 0 0"/>
  </joint>

  <link name="front_caster">
    <visual>
      <geometry>
        <sphere radius="0.06"/>
      </geometry>
      <material name="Cyan"/>
    </visual>

    <collision>
      <origin xyz="0 0 0" rpy="0 0 0"/>
      <geometry>
        <sphere radius="0.06"/>
      </geometry>
    </collision>

    <inertial>
      <origin xyz="0.0 0.0 0.0" rpy="0.0 0.0 0.0"/>
      <mass value="0.05"/>
      <inertia ixx="0.000072" ixy="0.0" ixz="0.0" iyy="0.000072" iyz="0.0" izz="0.000072"/>
    </inertial>

  </link>

  <!-- ___________________________________________________________________Laser___________________________________________________________________-->
  
  <joint name="laser_joint" type="fixed">
    <parent link="base_link"/>
    <child link="laser_link"/>
    <origin rpy="0  0  0" xyz="0.16 0 0.12"/>
    <axis xyz="0  0  0"/>
  </joint>

  <link name="laser_link">
    <inertial>
      <mass value="0.1"/>
      <origin rpy="0  0  0" xyz="0  0  0"/>
      <inertia ixx="0" ixy="0" ixz="0" iyy="0" iyz="0" izz="0"/>
    </inertial>

    <collision name="collision-base">
      <origin rpy="0  0  0" xyz="0  0  0"/>
      <geometry>
        <box size="0.05 0.05 0.041"/>
      </geometry>
    </collision>

    <visual name="visual-base">
      <origin rpy="0  0  0" xyz="0  0  0"/>
      <geometry>
        <box size="0.05 0.05 0.041"/>
      </geometry>
    </visual>

    <collision name="collision-top">
      <origin rpy="0  0  0" xyz="0  0  0.035"/>
      <geometry>
        <cylinder length="0.029" radius="0.021"/>
      </geometry>
    </collision>

    <visual name="visual-top">
      <origin rpy="0  0  0" xyz="0  0  0.035"/>
      <geometry>
        <cylinder length="0.029" radius="0.021"/>
      </geometry>
    </visual>

  </link>

</robot>
